Workbook

Sheet Cover
A1: AI-Supported Corporate Valuation: LSEG and the Limits of Automated Financial Analysis
A3: FY2025. Valuation reference: 26 February 2026. Price/share proxy disclosed 27 February. GBP millions except per share.
A5: Valuation summary
A6: Method | B6: Implied value / share | C6: Reference price | D6: Upside / (downside)
A7: DCF — principal method | B7: ='DCF'!$B$36 -> 122.91923 | C7: ='Assumptions'!$B$8 -> 81.266 | D7: =B7/C7-1 -> 0.51255423
A8: Comparable companies — cross-check | B8: ='Comps'!$B$21 -> 123.95991 | C8: ='Assumptions'!$B$8 -> 81.266 | D8: =B8/C8-1 -> 0.52536005
A9: Weighted indication | B9: =B7*'Assumptions'!$B$40+B8*'Assumptions'!$B$41 -> 123.23144 | C9: ='Assumptions'!$B$8 -> 81.266 | D9: =B9/C9-1 -> 0.51639598
A10: David's judgement | B10: =IF(D7>=15%,"POSITIVE / WATCH",IF(D7<=-15%,"NEGATIVE / AVOID","NEUTRAL / WATCH")) -> POSITIVE / WATCH | C10: ='Assumptions'!$B$8 -> 81.266 | D10: =D7 -> 0.51255423
A12: Investment and transaction judgement
A13: Investment: the live judgement is a valuation signal rather than a direct trading recommendation. At ≥15% DCF upside it shows POSITIVE / WATCH; between -15% and +15% it shows NEUTRAL / WATCH; and at ≤-15% it shows NEGATIVE / AVOID. DCF is the principal method and comparables are a reasonableness check. The conclusion is assumption-sensitive and remains subject to execution, leverage, forecast, dilution and terminal-value risk. Transaction: ATTRACTIVE STRATEGIC ASSET, PRICE-DISCIPLINED. A control premium is justified only with credible, quantified synergies; a highly levered acquisition would carry material integration and balance-sheet risk. This is a student case study, not investment advice.
A19: How to use the model
A20: Select a case in Assumptions!B5 and edit yellow inputs. Checks tests calculation consistency, not source completeness or investment quality. This is a retrospective FY2025 study: results were released 26 February 2026 and the price/share proxy was disclosed 27 February. It is not a strict information-available-at-26-February backtest or a 2025-only information set. See Sources for input limitations.

Sheet Assumptions
A1: Assumptions and Scenario Control
A3: Blue-font cells are editable. Forecast assumptions are explicitly separated from reported facts.
A4: Model control and market reference
A5: Scenario | B5: Base | D5: Price: £81.266 = 8,126.60p / 100. RNS published 27 Feb 2026 reports 34,592 shares bought on 26 Feb. Retained as a verified programme VWAP proxy, not the official close or all-market VWAP. Voting rights are the announced post-cancellation denominator, not diluted weighted-average shares. Source S3.
A6: Valuation date | B6: 2026-02-26
A7: Currency / units | B7: GBP millions
A8: Reference price (£) | B8: 81.266
A9: Voting shares used as proxy (m) | B9: 505.33252
A10: Operating net debt | B10: 8175 | D10: The proxy publication is one day after the valuation reference. No claim is made that these disclosed figures were public on 26 Feb. Operating net debt is still the FY2025 balance; no intervening debt/cash roll-forward is modelled.
A11: Risk-free rate | B11: 0.045
A12: Equity risk premium | B12: 0.045
A14: WACC
A15: Levered beta | B15: 0.9
A16: Pre-tax cost of debt | B16: 0.045
A17: Tax rate | B17: 0.245
A18: Market capitalisation | B18: =B8*B9 -> 41066.352
A19: Debt weight | B19: =B10/(B10+B18) -> 0.166019
A20: Equity weight | B20: =B18/(B10+B18) -> 0.833981
A21: Cost of equity | B21: =B11+B15*B12 -> 0.0855
A22: After-tax cost of debt | B22: =B16*(1-B17) -> 0.033975
A23: WACC | B23: =B20*B21+B19*B22 -> 0.076945871
A25: Operating cases
A26: Case | B26: 2026 growth | C26: 2027 growth | D26: 2028 growth | E26: 2029 growth | F26: 2030 growth | G26: 2030 EBITDA margin | H26: Terminal growth
A27: Downside | B27: 0.045 | C27: 0.045 | D27: 0.04 | E27: 0.04 | F27: 0.035 | G27: 0.515 | H27: 0.02
A28: Base | B28: 0.07 | C28: 0.065 | D28: 0.06 | E28: 0.06 | F28: 0.055 | G28: 0.54 | H28: 0.025
A29: Upside | B29: 0.085 | C29: 0.08 | D29: 0.075 | E29: 0.07 | F29: 0.065 | G29: 0.56 | H29: 0.03
A30: Selected | B30: =INDEX(B$27:B$29,MATCH($B$5,$A$27:$A$29,0)) -> 0.07 | C30: =INDEX(C$27:C$29,MATCH($B$5,$A$27:$A$29,0)) -> 0.065 | D30: =INDEX(D$27:D$29,MATCH($B$5,$A$27:$A$29,0)) -> 0.06 | E30: =INDEX(E$27:E$29,MATCH($B$5,$A$27:$A$29,0)) -> 0.06 | F30: =INDEX(F$27:F$29,MATCH($B$5,$A$27:$A$29,0)) -> 0.055 | G30: =INDEX(G$27:G$29,MATCH($B$5,$A$27:$A$29,0)) -> 0.54 | H30: =INDEX(H$27:H$29,MATCH($B$5,$A$27:$A$29,0)) -> 0.025
A32: Cash-flow drivers
A33: Driver | B33: Selected assumption | C33: Rationale | D33: 2026E | E33: 2027E | F33: 2028E | G33: 2029E | H33: 2030E
A34: D&A as % revenue | B34: 0.113 | C34: FY2025 adjusted EBITDA less adjusted operating profit, divided by income
A35: Capex as % revenue | B35: =D35 -> 0.095 | C35: Explicit annual path: 9.5% in 2026, declining to 8.0% by 2029 | D35: 0.095 | E35: 0.09 | F35: 0.085 | G35: 0.08 | H35: 0.08
A36: Change in NWC as % revenue | B36: 0.015 | C36: Normalised modelling assumption
A37: Cash tax rate | B37: 0.245 | C37: 2026 company guidance midpoint
A38: Terminal growth | B38: =H30 -> 0.025 | C38: Selected case
A39: Method weighting and interpretation
A40: DCF weight | B40: 0.7 | C40: Principal method: cash-flow based and linked to operating assumptions
A41: Comparable-company weight | B41: 0.3 | C41: Cross-check only because peer business mix and definitions differ
A42: Weight check | B42: =SUM(B40:B41) -> 1

Sheet Historical
A1: Historical Financials and Operating Review
A3: FY2025 preliminary results are the main source. Exact sections, reclassifications and legacy-input limitations are recorded in Sources.
A5: Income and cash flow
A6: GBP m unless stated | B6: 2023A | C6: 2024A | D6: 2025A
A7: Total income excl. recoveries | B7: 8061 | C7: 8494 | D7: 8986
A8: Growth | C8: =C7/B7-1 -> 0.05371542 | D8: =D7/C7-1 -> 0.05792324
A9: Adjusted EBITDA | B9: 3801 | C9: 4148 | D9: 4523
A10: Adjusted EBITDA margin | B10: =B9/B7 -> 0.47152959 | C10: =C9/C7 -> 0.48834471 | D10: =D9/D7 -> 0.50333853
A11: Adjusted operating profit | B11: 2909 | C11: 3165 | D11: 3506
A12: D&A / impairment (derived) | B12: =B9-B11 -> 892 | C12: =C9-C11 -> 983 | D12: =D9-D11 -> 1017
A13: Reported EBITDA | C13: 3945 | D13: 4365
A14: Change in working capital | C14: -50 | D14: -419
A15: Capex | C15: -957 | D15: -919
A16: Equity free cash flow | C16: 2184 | D16: 2445
A17: Operating net debt | C17: 7178 | D17: 8175
A18: Voting shares at FY2025 reporting (m) | D18: 510.40807
A20: AI-supported document review
A21: Finding | B21: Evidence | C21: Valuation implication | D21: Confidence | E21: Human check | F21: Source ID | G21: Treatment
A22: Revenue quality | B22: ASV +5.9%; subscription-led data businesses | C22: Supports durable growth | D22: High | E22: Confirmed | F22: S1 | G22: Base growth anchored to guidance
A23: Margin expansion | B23: 2025 adjusted EBITDA margin 50.3% | C23: Operating leverage supports FCF | D23: High | E23: Confirmed | F23: S1 | G23: Margin ramps by case
A24: Capital intensity | B24: 2025 capex intensity 10.2% | C24: Near-term FCF burden eases | D24: High | E24: Confirmed | F24: S1 | G24: Capex declines toward 8%
A25: Leverage | B25: Operating net debt £8.175bn | C25: Reduces equity value | D25: High | E25: Confirmed | F25: S1 | G25: Full equity bridge deduction
A26: AI opportunity | B26: AI-ready data partnerships | C26: Potential upside, execution risk | D26: Medium | E26: Confirmed | F26: S1 | G26: Upside case only
A27: Model risk | B27: Forecasts require assumptions | C27: Avoid false precision | D27: High | E27: Confirmed | F27: S10 | G27: Scenarios and sensitivities

Sheet DCF
A1: Discounted Cash Flow Valuation
A3: Unlevered FCF | Gordon growth terminal value | Year-end discounting | GBP millions except per share
A5: Forecast
A6: GBP m unless stated | B6: 2025A | C6: 2026E | D6: 2027E | E6: 2028E | F6: 2029E | G6: 2030E
A7: Revenue growth | B7: 0.05792324 | C7: ='Assumptions'!B$30 -> 0.07 | D7: ='Assumptions'!C$30 -> 0.065 | E7: ='Assumptions'!D$30 -> 0.06 | F7: ='Assumptions'!E$30 -> 0.06 | G7: ='Assumptions'!F$30 -> 0.055
A8: Revenue | B8: 8986 | C8: =B8*(1+C7) -> 9615.02 | D8: =C8*(1+D7) -> 10239.996 | E8: =D8*(1+E7) -> 10854.396 | F8: =E8*(1+F7) -> 11505.66 | G8: =F8*(1+G7) -> 12138.471
A9: EBITDA margin | B9: 0.50333853 | C9: =$B$9+('Assumptions'!$G$30-$B$9)*(1/5) -> 0.51067082 | D9: =$B$9+('Assumptions'!$G$30-$B$9)*(2/5) -> 0.51800312 | E9: =$B$9+('Assumptions'!$G$30-$B$9)*(3/5) -> 0.52533541 | F9: =$B$9+('Assumptions'!$G$30-$B$9)*(4/5) -> 0.53266771 | G9: =$B$9+('Assumptions'!$G$30-$B$9)*(5/5) -> 0.54
A10: Adjusted EBITDA | B10: 4523 | C10: =C8*C9 -> 4910.1102 | D10: =D8*D9 -> 5304.35 | E10: =E8*E9 -> 5702.1986 | F10: =F8*F9 -> 6128.6934 | G10: =G8*G9 -> 6554.7744
A11: D&A / impairment | B11: 1017 | C11: =C8*'Assumptions'!$B$34 -> 1086.4973 | D11: =D8*'Assumptions'!$B$34 -> 1157.1196 | E11: =E8*'Assumptions'!$B$34 -> 1226.5468 | F11: =F8*'Assumptions'!$B$34 -> 1300.1396 | G11: =G8*'Assumptions'!$B$34 -> 1371.6472
A12: EBIT | B12: 3506 | C12: =C10-C11 -> 3823.6129 | D12: =D10-D11 -> 4147.2304 | E12: =E10-E11 -> 4475.6519 | F12: =F10-F11 -> 4828.5539 | G12: =G10-G11 -> 5183.1272
A13: Cash tax | B13: -859 | C13: =-C12*'Assumptions'!$B$37 -> -936.78516 | D13: =-D12*'Assumptions'!$B$37 -> -1016.0715 | E13: =-E12*'Assumptions'!$B$37 -> -1096.5347 | F13: =-F12*'Assumptions'!$B$37 -> -1182.9957 | G13: =-G12*'Assumptions'!$B$37 -> -1269.8662
A14: NOPAT | B14: 2647 | C14: =C12+C13 -> 2886.8277 | D14: =D12+D13 -> 3131.159 | E14: =E12+E13 -> 3379.1172 | F14: =F12+F13 -> 3645.5582 | G14: =G12+G13 -> 3913.261
A15: D&A add-back | B15: 1017 | C15: =C11 -> 1086.4973 | D15: =D11 -> 1157.1196 | E15: =E11 -> 1226.5468 | F15: =F11 -> 1300.1396 | G15: =G11 -> 1371.6472
A16: Capex | B16: -919 | C16: =-C8*'Assumptions'!$D$35 -> -913.4269 | D16: =-D8*'Assumptions'!$E$35 -> -921.59967 | E16: =-E8*'Assumptions'!$F$35 -> -922.62367 | F16: =-F8*'Assumptions'!$G$35 -> -920.45279 | G16: =-G8*'Assumptions'!$H$35 -> -971.07769
A17: Change in NWC | B17: -419 | C17: =-C8*'Assumptions'!$B$36 -> -144.2253 | D17: =-D8*'Assumptions'!$B$36 -> -153.59994 | E17: =-E8*'Assumptions'!$B$36 -> -162.81594 | F17: =-F8*'Assumptions'!$B$36 -> -172.5849 | G17: =-G8*'Assumptions'!$B$36 -> -182.07707
A18: Unlevered FCF | B18: 2326 | C18: =SUM(C14:C17) -> 2915.6728 | D18: =SUM(D14:D17) -> 3213.0789 | E18: =SUM(E14:E17) -> 3520.2243 | F18: =SUM(F14:F17) -> 3852.66 | G18: =SUM(G14:G17) -> 4131.7535
A19: Discount period | B19: 0 | C19: =1 -> 1 | D19: =2 -> 2 | E19: =3 -> 3 | F19: =4 -> 4 | G19: =5 -> 5
A20: Discount factor | B20: 1 | C20: =1/(1+'Assumptions'!$B$23)^1 -> 0.92855177 | D20: =1/(1+'Assumptions'!$B$23)^2 -> 0.8622084 | E20: =1/(1+'Assumptions'!$B$23)^3 -> 0.80060514 | F20: =1/(1+'Assumptions'!$B$23)^4 -> 0.74340332 | G20: =1/(1+'Assumptions'!$B$23)^5 -> 0.69028847
A21: PV of FCF | B21: 2326 | C21: =C18*C20 -> 2707.3532 | D21: =D18*D20 -> 2770.3436 | E21: =E18*E20 -> 2818.3097 | F21: =F18*F20 -> 2864.0803 | G21: =G18*G20 -> 2852.1018
A24: Terminal value and equity bridge
A25: Terminal year FCF | B25: =G18 -> 4131.7535
A26: Terminal growth | B26: ='Assumptions'!$B$38 -> 0.025
A27: WACC | B27: ='Assumptions'!$B$23 -> 0.076945871
A28: Terminal value | B28: =B25*(1+B26)/(B27-B26) -> 81528.084
A29: PV factor | B29: =G20 -> 0.69028847
A30: PV of terminal value | B30: =B28*B29 -> 56277.897
A31: PV of forecast FCF | B31: =SUM(C21:G21) -> 14012.189
A32: Enterprise value | B32: =SUM(B30:B31) -> 70290.085
A33: Less: operating net debt | B33: =-'Assumptions'!$B$10 -> -8175
A34: Equity value | B34: =SUM(B32:B33) -> 62115.085
A35: Voting shares used as proxy (m) | B35: ='Assumptions'!$B$9 -> 505.33252
A36: DCF value per share | B36: =B34/B35 -> 122.91923
A37: Reference share price | B37: ='Assumptions'!$B$8 -> 81.266
A38: Upside / (downside) | B38: =B36/B37-1 -> 0.51255423

Sheet Comps
A1: Comparable-Company Analysis
A3: Market prices fixed at 26 February 2026; financials are FY2025. EV/adjusted EBIT is used consistently. This is a reasonableness check, not the principal valuation.
A5: Peer screen
A6: Company | B6: Ticker | C6: Price | D6: Shares m | E6: Market cap LC m | F6: Net debt LC m | G6: Revenue LC m | H6: Adjusted EBIT LC m | I6: EV / Revenue | J6: EV / Adj. EBIT | K6: P / E
A7: LSEG | B7: LSEG.L | C7: 81.266 | D7: 505.33252 | E7: =C7*D7 -> 41066.352 | F7: 8175 | G7: 8986 | H7: 3506 | I7: =(E7+F7)/G7 -> 5.4797855 | J7: =(E7+F7)/H7 -> 14.044881 | K7: 19.32
A8: Intercontinental Exchange | B8: ICE | C8: 162.89 | D8: 575 | E8: =C8*D8 -> 93661.75 | F8: 18763 | G8: 9931 | H8: 5959 | I8: =(E8+F8)/G8 -> 11.320587 | J8: =(E8+F8)/H8 -> 18.866379 | K8: 23.3
A9: CME Group | B9: CME | C9: 316.45 | D9: 361 | E9: =C9*D9 -> 114238.45 | F9: -1200 | G9: 6520.6 | H9: 4524.8 | I9: =(E9+F9)/G9 -> 17.33559 | J9: =(E9+F9)/H9 -> 24.981977 | K9: 28.25
A10: Nasdaq | B10: NDAQ | C10: 88.59 | D10: 575 | E10: =C10*D10 -> 50939.25 | F10: 8000 | G10: 5249 | H10: 2918 | I10: =(E10+F10)/G10 -> 11.228663 | J10: =(E10+F10)/H10 -> 20.198509 | K10: 25.46
A11: Median | J11: =MEDIAN(J8:J10) -> 20.198509 | K11: =MEDIAN(K8:K10) -> 25.46
A14: LSEG implied value
A15: Selected peer median EV / adjusted EBIT | B15: =J11 -> 20.198509
A16: LSEG 2025 adjusted operating profit | B16: ='Historical'!D11 -> 3506
A17: Implied enterprise value | B17: =B15*B16 -> 70815.973
A18: Less operating net debt | B18: =-'Assumptions'!$B$10 -> -8175
A19: Implied equity value | B19: =SUM(B17:B18) -> 62640.973
A20: Voting shares used as proxy (m) | B20: ='Assumptions'!$B$9 -> 505.33252
A21: Implied value / share | B21: =B19/B20 -> 123.95991
A23: EV/adjusted EBIT uses a common metric label, but company adjustments and business mix still differ. Some peer shares, net-debt figures and P/E inputs remain approximate or unreconciled legacy inputs (Sources). The P/E median cache is corrected to 25.46x, but P/E is descriptive and does not drive value. The £123.96 result is an indicative screening cross-check, not a fully harmonised target price.

Sheet Scenarios
A1: Base, Upside and Downside Cases
A3: Case values recalculate the underlying DCF using case-specific growth, margins and terminal growth.
A5: Case valuation
A6: Case | B6: Revenue CAGR | C6: 2030 revenue | D6: 2030 margin | E6: 2030 EBITDA | F6: Terminal growth | G6: Enterprise value | H6: Value / share
A7: Downside | B7: =((1+'Assumptions'!$B$27)*(1+'Assumptions'!$C$27)*(1+'Assumptions'!$D$27)*(1+'Assumptions'!$E$27)*(1+'Assumptions'!$F$27))^(1/5)-1 -> 0.04099327 | C7: ='Historical'!$D$7*(1+'Assumptions'!$B$27)*(1+'Assumptions'!$C$27)*(1+'Assumptions'!$D$27)*(1+'Assumptions'!$E$27)*(1+'Assumptions'!$F$27) -> 10985.151 | D7: ='Assumptions'!$G$27 -> 0.515 | E7: =C7*D7 -> 5657.3527 | F7: ='Assumptions'!$H$27 -> 0.02 | G7: =((('Historical'!$D$7*(1+'Assumptions'!$B$27))*('Historical'!$D$10+('Assumptions'!$G$27-'Historical'!$D$10)*1/5)*(1-'Assumptions'!$B$37)+('Historical'!$D$7*(1+'Assumptions'!$B$27))*'Assumptions'!$B$34*'Assumptions'!$B$37-('Historical'!$D$7*(1+'Assumptions'!$B$27))*'Assumptions'!$D$35-('Historical'!$D$7*(1+'Assumptions'!$B$27))*'Assumptions'!$B$36))/(1+'Assumptions'!$B$23)^1+((('Historical'!$D$7*(1+'Assumptions'!$B$27)*(1+'Assumptions'!$C$27))*('Historical'!$D$10+('Assumptions'!$G$27-'Historical'!$D$10)*2/5)*(1-'Assumptions'!$B$37)+('Historical'!$D$7*(1+'Assumptions'!$B$27)*(1+'Assumptions'!$C$27))*'Assumptions'!$B$34*'Assumptions'!$B$37-('Historical'!$D$7*(1+'Assumptions'!$B$27)*(1+'Assumptions'!$C$27))*'Assumptions'!$E$35-('Historical'!$D$7*(1+'Assumptions'!$B$27)*(1+'Assumptions'!$C$27))*'Assumptions'!$B$36))/(1+'Assumptions'!$B$23)^2+((('Historical'!$D$7*(1+'Assumptions'!$B$27)*(1+'Assumptions'!$C$27)*(1+'Assumptions'!$D$27))*('Historical'!$D$10+('Assumptions'!$G$27-'Historical'!$D$10)*3/5)*(1-'Assumptions'!$B$37)+('Historical'!$D$7*(1+'Assumptions'!$B$27)*(1+'Assumptions'!$C$27)*(1+'Assumptions'!$D$27))*'Assumptions'!$B$34*'Assumptions'!$B$37-('Historical'!$D$7*(1+'Assumptions'!$B$27)*(1+'Assumptions'!$C$27)*(1+'Assumptions'!$D$27))*'Assumptions'!$F$35-('Historical'!$D$7*(1+'Assumptions'!$B$27)*(1+'Assumptions'!$C$27)*(1+'Assumptions'!$D$27))*'Assumptions'!$B$36))/(1+'Assumptions'!$B$23)^3+((('Historical'!$D$7*(1+'Assumptions'!$B$27)*(1+'Assumptions'!$C$27)*(1+'Assumptions'!$D$27)*(1+'Assumptions'!$E$27))*('Historical'!$D$10+('Assumptions'!$G$27-'Historical'!$D$10)*4/5)*(1-'Assumptions'!$B$37)+('Historical'!$D$7*(1+'Assumptions'!$B$27)*(1+'Assumptions'!$C$27)*(1+'Assumptions'!$D$27)*(1+'Assumptions'!$E$27))*'Assumptions'!$B$34*'Assumptions'!$B$37-('Historical'!$D$7*(1+'Assumptions'!$B$27)*(1+'Assumptions'!$C$27)*(1+'Assumptions'!$D$27)*(1+'Assumptions'!$E$27))*'Assumptions'!$G$35-('Historical'!$D$7*(1+'Assumptions'!$B$27)*(1+'Assumptions'!$C$27)*(1+'Assumptions'!$D$27)*(1+'Assumptions'!$E$27))*'Assumptions'!$B$36))/(1+'Assumptions'!$B$23)^4+((('Historical'!$D$7*(1+'Assumptions'!$B$27)*(1+'Assumptions'!$C$27)*(1+'Assumptions'!$D$27)*(1+'Assumptions'!$E$27)*(1+'Assumptions'!$F$27))*('Historical'!$D$10+('Assumptions'!$G$27-'Historical'!$D$10)*5/5)*(1-'Assumptions'!$B$37)+('Historical'!$D$7*(1+'Assumptions'!$B$27)*(1+'Assumptions'!$C$27)*(1+'Assumptions'!$D$27)*(1+'Assumptions'!$E$27)*(1+'Assumptions'!$F$27))*'Assumptions'!$B$34*'Assumptions'!$B$37-('Historical'!$D$7*(1+'Assumptions'!$B$27)*(1+'Assumptions'!$C$27)*(1+'Assumptions'!$D$27)*(1+'Assumptions'!$E$27)*(1+'Assumptions'!$F$27))*'Assumptions'!$H$35-('Historical'!$D$7*(1+'Assumptions'!$B$27)*(1+'Assumptions'!$C$27)*(1+'Assumptions'!$D$27)*(1+'Assumptions'!$E$27)*(1+'Assumptions'!$F$27))*'Assumptions'!$B$36))/(1+'Assumptions'!$B$23)^5+((('Historical'!$D$7*(1+'Assumptions'!$B$27)*(1+'Assumptions'!$C$27)*(1+'Assumptions'!$D$27)*(1+'Assumptions'!$E$27)*(1+'Assumptions'!$F$27))*('Historical'!$D$10+('Assumptions'!$G$27-'Historical'!$D$10)*5/5)*(1-'Assumptions'!$B$37)+('Historical'!$D$7*(1+'Assumptions'!$B$27)*(1+'Assumptions'!$C$27)*(1+'Assumptions'!$D$27)*(1+'Assumptions'!$E$27)*(1+'Assumptions'!$F$27))*'Assumptions'!$B$34*'Assumptions'!$B$37-('Historical'!$D$7*(1+'Assumptions'!$B$27)*(1+'Assumptions'!$C$27)*(1+'Assumptions'!$D$27)*(1+'Assumptions'!$E$27)*(1+'Assumptions'!$F$27))*'Assumptions'!$H$35-('Historical'!$D$7*(1+'Assumptions'!$B$27)*(1+'Assumptions'!$C$27)*(1+'Assumptions'!$D$27)*(1+'Assumptions'!$E$27)*(1+'Assumptions'!$F$27))*'Assumptions'!$B$36))*(1+'Assumptions'!$H$27)/('Assumptions'!$B$23-'Assumptions'!$H$27)/(1+'Assumptions'!$B$23)^5 -> 56388.853 | H7: =(G7-'Assumptions'!$B$10)/'Assumptions'!$B$9 -> 95.410153
A8: Base | B8: =((1+'Assumptions'!$B$28)*(1+'Assumptions'!$C$28)*(1+'Assumptions'!$D$28)*(1+'Assumptions'!$E$28)*(1+'Assumptions'!$F$28))^(1/5)-1 -> 0.061987769 | C8: ='Historical'!$D$7*(1+'Assumptions'!$B$28)*(1+'Assumptions'!$C$28)*(1+'Assumptions'!$D$28)*(1+'Assumptions'!$E$28)*(1+'Assumptions'!$F$28) -> 12138.471 | D8: ='Assumptions'!$G$28 -> 0.54 | E8: =C8*D8 -> 6554.7744 | F8: ='Assumptions'!$H$28 -> 0.025 | G8: =((('Historical'!$D$7*(1+'Assumptions'!$B$28))*('Historical'!$D$10+('Assumptions'!$G$28-'Historical'!$D$10)*1/5)*(1-'Assumptions'!$B$37)+('Historical'!$D$7*(1+'Assumptions'!$B$28))*'Assumptions'!$B$34*'Assumptions'!$B$37-('Historical'!$D$7*(1+'Assumptions'!$B$28))*'Assumptions'!$D$35-('Historical'!$D$7*(1+'Assumptions'!$B$28))*'Assumptions'!$B$36))/(1+'Assumptions'!$B$23)^1+((('Historical'!$D$7*(1+'Assumptions'!$B$28)*(1+'Assumptions'!$C$28))*('Historical'!$D$10+('Assumptions'!$G$28-'Historical'!$D$10)*2/5)*(1-'Assumptions'!$B$37)+('Historical'!$D$7*(1+'Assumptions'!$B$28)*(1+'Assumptions'!$C$28))*'Assumptions'!$B$34*'Assumptions'!$B$37-('Historical'!$D$7*(1+'Assumptions'!$B$28)*(1+'Assumptions'!$C$28))*'Assumptions'!$E$35-('Historical'!$D$7*(1+'Assumptions'!$B$28)*(1+'Assumptions'!$C$28))*'Assumptions'!$B$36))/(1+'Assumptions'!$B$23)^2+((('Historical'!$D$7*(1+'Assumptions'!$B$28)*(1+'Assumptions'!$C$28)*(1+'Assumptions'!$D$28))*('Historical'!$D$10+('Assumptions'!$G$28-'Historical'!$D$10)*3/5)*(1-'Assumptions'!$B$37)+('Historical'!$D$7*(1+'Assumptions'!$B$28)*(1+'Assumptions'!$C$28)*(1+'Assumptions'!$D$28))*'Assumptions'!$B$34*'Assumptions'!$B$37-('Historical'!$D$7*(1+'Assumptions'!$B$28)*(1+'Assumptions'!$C$28)*(1+'Assumptions'!$D$28))*'Assumptions'!$F$35-('Historical'!$D$7*(1+'Assumptions'!$B$28)*(1+'Assumptions'!$C$28)*(1+'Assumptions'!$D$28))*'Assumptions'!$B$36))/(1+'Assumptions'!$B$23)^3+((('Historical'!$D$7*(1+'Assumptions'!$B$28)*(1+'Assumptions'!$C$28)*(1+'Assumptions'!$D$28)*(1+'Assumptions'!$E$28))*('Historical'!$D$10+('Assumptions'!$G$28-'Historical'!$D$10)*4/5)*(1-'Assumptions'!$B$37)+('Historical'!$D$7*(1+'Assumptions'!$B$28)*(1+'Assumptions'!$C$28)*(1+'Assumptions'!$D$28)*(1+'Assumptions'!$E$28))*'Assumptions'!$B$34*'Assumptions'!$B$37-('Historical'!$D$7*(1+'Assumptions'!$B$28)*(1+'Assumptions'!$C$28)*(1+'Assumptions'!$D$28)*(1+'Assumptions'!$E$28))*'Assumptions'!$G$35-('Historical'!$D$7*(1+'Assumptions'!$B$28)*(1+'Assumptions'!$C$28)*(1+'Assumptions'!$D$28)*(1+'Assumptions'!$E$28))*'Assumptions'!$B$36))/(1+'Assumptions'!$B$23)^4+((('Historical'!$D$7*(1+'Assumptions'!$B$28)*(1+'Assumptions'!$C$28)*(1+'Assumptions'!$D$28)*(1+'Assumptions'!$E$28)*(1+'Assumptions'!$F$28))*('Historical'!$D$10+('Assumptions'!$G$28-'Historical'!$D$10)*5/5)*(1-'Assumptions'!$B$37)+('Historical'!$D$7*(1+'Assumptions'!$B$28)*(1+'Assumptions'!$C$28)*(1+'Assumptions'!$D$28)*(1+'Assumptions'!$E$28)*(1+'Assumptions'!$F$28))*'Assumptions'!$B$34*'Assumptions'!$B$37-('Historical'!$D$7*(1+'Assumptions'!$B$28)*(1+'Assumptions'!$C$28)*(1+'Assumptions'!$D$28)*(1+'Assumptions'!$E$28)*(1+'Assumptions'!$F$28))*'Assumptions'!$H$35-('Historical'!$D$7*(1+'Assumptions'!$B$28)*(1+'Assumptions'!$C$28)*(1+'Assumptions'!$D$28)*(1+'Assumptions'!$E$28)*(1+'Assumptions'!$F$28))*'Assumptions'!$B$36))/(1+'Assumptions'!$B$23)^5+((('Historical'!$D$7*(1+'Assumptions'!$B$28)*(1+'Assumptions'!$C$28)*(1+'Assumptions'!$D$28)*(1+'Assumptions'!$E$28)*(1+'Assumptions'!$F$28))*('Historical'!$D$10+('Assumptions'!$G$28-'Historical'!$D$10)*5/5)*(1-'Assumptions'!$B$37)+('Historical'!$D$7*(1+'Assumptions'!$B$28)*(1+'Assumptions'!$C$28)*(1+'Assumptions'!$D$28)*(1+'Assumptions'!$E$28)*(1+'Assumptions'!$F$28))*'Assumptions'!$B$34*'Assumptions'!$B$37-('Historical'!$D$7*(1+'Assumptions'!$B$28)*(1+'Assumptions'!$C$28)*(1+'Assumptions'!$D$28)*(1+'Assumptions'!$E$28)*(1+'Assumptions'!$F$28))*'Assumptions'!$H$35-('Historical'!$D$7*(1+'Assumptions'!$B$28)*(1+'Assumptions'!$C$28)*(1+'Assumptions'!$D$28)*(1+'Assumptions'!$E$28)*(1+'Assumptions'!$F$28))*'Assumptions'!$B$36))*(1+'Assumptions'!$H$28)/('Assumptions'!$B$23-'Assumptions'!$H$28)/(1+'Assumptions'!$B$23)^5 -> 70290.085 | H8: =(G8-'Assumptions'!$B$10)/'Assumptions'!$B$9 -> 122.91923
A9: Upside | B9: =((1+'Assumptions'!$B$29)*(1+'Assumptions'!$C$29)*(1+'Assumptions'!$D$29)*(1+'Assumptions'!$E$29)*(1+'Assumptions'!$F$29))^(1/5)-1 -> 0.074976744 | C9: ='Historical'!$D$7*(1+'Assumptions'!$B$29)*(1+'Assumptions'!$C$29)*(1+'Assumptions'!$D$29)*(1+'Assumptions'!$E$29)*(1+'Assumptions'!$F$29) -> 12899.17 | D9: ='Assumptions'!$G$29 -> 0.56 | E9: =C9*D9 -> 7223.5351 | F9: ='Assumptions'!$H$29 -> 0.03 | G9: =((('Historical'!$D$7*(1+'Assumptions'!$B$29))*('Historical'!$D$10+('Assumptions'!$G$29-'Historical'!$D$10)*1/5)*(1-'Assumptions'!$B$37)+('Historical'!$D$7*(1+'Assumptions'!$B$29))*'Assumptions'!$B$34*'Assumptions'!$B$37-('Historical'!$D$7*(1+'Assumptions'!$B$29))*'Assumptions'!$D$35-('Historical'!$D$7*(1+'Assumptions'!$B$29))*'Assumptions'!$B$36))/(1+'Assumptions'!$B$23)^1+((('Historical'!$D$7*(1+'Assumptions'!$B$29)*(1+'Assumptions'!$C$29))*('Historical'!$D$10+('Assumptions'!$G$29-'Historical'!$D$10)*2/5)*(1-'Assumptions'!$B$37)+('Historical'!$D$7*(1+'Assumptions'!$B$29)*(1+'Assumptions'!$C$29))*'Assumptions'!$B$34*'Assumptions'!$B$37-('Historical'!$D$7*(1+'Assumptions'!$B$29)*(1+'Assumptions'!$C$29))*'Assumptions'!$E$35-('Historical'!$D$7*(1+'Assumptions'!$B$29)*(1+'Assumptions'!$C$29))*'Assumptions'!$B$36))/(1+'Assumptions'!$B$23)^2+((('Historical'!$D$7*(1+'Assumptions'!$B$29)*(1+'Assumptions'!$C$29)*(1+'Assumptions'!$D$29))*('Historical'!$D$10+('Assumptions'!$G$29-'Historical'!$D$10)*3/5)*(1-'Assumptions'!$B$37)+('Historical'!$D$7*(1+'Assumptions'!$B$29)*(1+'Assumptions'!$C$29)*(1+'Assumptions'!$D$29))*'Assumptions'!$B$34*'Assumptions'!$B$37-('Historical'!$D$7*(1+'Assumptions'!$B$29)*(1+'Assumptions'!$C$29)*(1+'Assumptions'!$D$29))*'Assumptions'!$F$35-('Historical'!$D$7*(1+'Assumptions'!$B$29)*(1+'Assumptions'!$C$29)*(1+'Assumptions'!$D$29))*'Assumptions'!$B$36))/(1+'Assumptions'!$B$23)^3+((('Historical'!$D$7*(1+'Assumptions'!$B$29)*(1+'Assumptions'!$C$29)*(1+'Assumptions'!$D$29)*(1+'Assumptions'!$E$29))*('Historical'!$D$10+('Assumptions'!$G$29-'Historical'!$D$10)*4/5)*(1-'Assumptions'!$B$37)+('Historical'!$D$7*(1+'Assumptions'!$B$29)*(1+'Assumptions'!$C$29)*(1+'Assumptions'!$D$29)*(1+'Assumptions'!$E$29))*'Assumptions'!$B$34*'Assumptions'!$B$37-('Historical'!$D$7*(1+'Assumptions'!$B$29)*(1+'Assumptions'!$C$29)*(1+'Assumptions'!$D$29)*(1+'Assumptions'!$E$29))*'Assumptions'!$G$35-('Historical'!$D$7*(1+'Assumptions'!$B$29)*(1+'Assumptions'!$C$29)*(1+'Assumptions'!$D$29)*(1+'Assumptions'!$E$29))*'Assumptions'!$B$36))/(1+'Assumptions'!$B$23)^4+((('Historical'!$D$7*(1+'Assumptions'!$B$29)*(1+'Assumptions'!$C$29)*(1+'Assumptions'!$D$29)*(1+'Assumptions'!$E$29)*(1+'Assumptions'!$F$29))*('Historical'!$D$10+('Assumptions'!$G$29-'Historical'!$D$10)*5/5)*(1-'Assumptions'!$B$37)+('Historical'!$D$7*(1+'Assumptions'!$B$29)*(1+'Assumptions'!$C$29)*(1+'Assumptions'!$D$29)*(1+'Assumptions'!$E$29)*(1+'Assumptions'!$F$29))*'Assumptions'!$B$34*'Assumptions'!$B$37-('Historical'!$D$7*(1+'Assumptions'!$B$29)*(1+'Assumptions'!$C$29)*(1+'Assumptions'!$D$29)*(1+'Assumptions'!$E$29)*(1+'Assumptions'!$F$29))*'Assumptions'!$H$35-('Historical'!$D$7*(1+'Assumptions'!$B$29)*(1+'Assumptions'!$C$29)*(1+'Assumptions'!$D$29)*(1+'Assumptions'!$E$29)*(1+'Assumptions'!$F$29))*'Assumptions'!$B$36))/(1+'Assumptions'!$B$23)^5+((('Historical'!$D$7*(1+'Assumptions'!$B$29)*(1+'Assumptions'!$C$29)*(1+'Assumptions'!$D$29)*(1+'Assumptions'!$E$29)*(1+'Assumptions'!$F$29))*('Historical'!$D$10+('Assumptions'!$G$29-'Historical'!$D$10)*5/5)*(1-'Assumptions'!$B$37)+('Historical'!$D$7*(1+'Assumptions'!$B$29)*(1+'Assumptions'!$C$29)*(1+'Assumptions'!$D$29)*(1+'Assumptions'!$E$29)*(1+'Assumptions'!$F$29))*'Assumptions'!$B$34*'Assumptions'!$B$37-('Historical'!$D$7*(1+'Assumptions'!$B$29)*(1+'Assumptions'!$C$29)*(1+'Assumptions'!$D$29)*(1+'Assumptions'!$E$29)*(1+'Assumptions'!$F$29))*'Assumptions'!$H$35-('Historical'!$D$7*(1+'Assumptions'!$B$29)*(1+'Assumptions'!$C$29)*(1+'Assumptions'!$D$29)*(1+'Assumptions'!$E$29)*(1+'Assumptions'!$F$29))*'Assumptions'!$B$36))*(1+'Assumptions'!$H$29)/('Assumptions'!$B$23-'Assumptions'!$H$29)/(1+'Assumptions'!$B$23)^5 -> 84433.464 | H9: =(G9-'Assumptions'!$B$10)/'Assumptions'!$B$9 -> 150.90749

Sheet Sensitivities
A1: DCF Sensitivities
A3: Sensitivity outputs independently recalculate the valuation mechanics.
A5: Value per share: WACC vs terminal growth
A6: WACC / TGR | B6: 0.015 | C6: 0.02 | D6: 0.025 | E6: 0.03 | F6: 0.035
A7: 0.065 | B7: =(SUMPRODUCT('DCF'!$C$18:$G$18,1/(1+$A7)^'DCF'!$C$19:$G$19)+'DCF'!$G$18*(1+B$6)/($A7-B$6)/(1+$A7)^5-'Assumptions'!$B$10)/'Assumptions'!$B$9 -> 133.65197 | C7: =(SUMPRODUCT('DCF'!$C$18:$G$18,1/(1+$A7)^'DCF'!$C$19:$G$19)+'DCF'!$G$18*(1+C$6)/($A7-C$6)/(1+$A7)^5-'Assumptions'!$B$10)/'Assumptions'!$B$9 -> 147.77559 | D7: =(SUMPRODUCT('DCF'!$C$18:$G$18,1/(1+$A7)^'DCF'!$C$19:$G$19)+'DCF'!$G$18*(1+D$6)/($A7-D$6)/(1+$A7)^5-'Assumptions'!$B$10)/'Assumptions'!$B$9 -> 165.43013 | E7: =(SUMPRODUCT('DCF'!$C$18:$G$18,1/(1+$A7)^'DCF'!$C$19:$G$19)+'DCF'!$G$18*(1+E$6)/($A7-E$6)/(1+$A7)^5-'Assumptions'!$B$10)/'Assumptions'!$B$9 -> 188.12881 | F7: =(SUMPRODUCT('DCF'!$C$18:$G$18,1/(1+$A7)^'DCF'!$C$19:$G$19)+'DCF'!$G$18*(1+F$6)/($A7-F$6)/(1+$A7)^5-'Assumptions'!$B$10)/'Assumptions'!$B$9 -> 218.39373
A8: 0.07 | B8: =(SUMPRODUCT('DCF'!$C$18:$G$18,1/(1+$A8)^'DCF'!$C$19:$G$19)+'DCF'!$G$18*(1+B$6)/($A8-B$6)/(1+$A8)^5-'Assumptions'!$B$10)/'Assumptions'!$B$9 -> 119.68337 | C8: =(SUMPRODUCT('DCF'!$C$18:$G$18,1/(1+$A8)^'DCF'!$C$19:$G$19)+'DCF'!$G$18*(1+C$6)/($A8-C$6)/(1+$A8)^5-'Assumptions'!$B$10)/'Assumptions'!$B$9 -> 131.02458 | D8: =(SUMPRODUCT('DCF'!$C$18:$G$18,1/(1+$A8)^'DCF'!$C$19:$G$19)+'DCF'!$G$18*(1+D$6)/($A8-D$6)/(1+$A8)^5-'Assumptions'!$B$10)/'Assumptions'!$B$9 -> 144.88606 | E8: =(SUMPRODUCT('DCF'!$C$18:$G$18,1/(1+$A8)^'DCF'!$C$19:$G$19)+'DCF'!$G$18*(1+E$6)/($A8-E$6)/(1+$A8)^5-'Assumptions'!$B$10)/'Assumptions'!$B$9 -> 162.21291 | F8: =(SUMPRODUCT('DCF'!$C$18:$G$18,1/(1+$A8)^'DCF'!$C$19:$G$19)+'DCF'!$G$18*(1+F$6)/($A8-F$6)/(1+$A8)^5-'Assumptions'!$B$10)/'Assumptions'!$B$9 -> 184.49028
A9: 0.075 | B9: =(SUMPRODUCT('DCF'!$C$18:$G$18,1/(1+$A9)^'DCF'!$C$19:$G$19)+'DCF'!$G$18*(1+B$6)/($A9-B$6)/(1+$A9)^5-'Assumptions'!$B$10)/'Assumptions'!$B$9 -> 108.0486 | C9: =(SUMPRODUCT('DCF'!$C$18:$G$18,1/(1+$A9)^'DCF'!$C$19:$G$19)+'DCF'!$G$18*(1+C$6)/($A9-C$6)/(1+$A9)^5-'Assumptions'!$B$10)/'Assumptions'!$B$9 -> 117.325 | D9: =(SUMPRODUCT('DCF'!$C$18:$G$18,1/(1+$A9)^'DCF'!$C$19:$G$19)+'DCF'!$G$18*(1+D$6)/($A9-D$6)/(1+$A9)^5-'Assumptions'!$B$10)/'Assumptions'!$B$9 -> 128.45668 | E9: =(SUMPRODUCT('DCF'!$C$18:$G$18,1/(1+$A9)^'DCF'!$C$19:$G$19)+'DCF'!$G$18*(1+E$6)/($A9-E$6)/(1+$A9)^5-'Assumptions'!$B$10)/'Assumptions'!$B$9 -> 142.06206 | F9: =(SUMPRODUCT('DCF'!$C$18:$G$18,1/(1+$A9)^'DCF'!$C$19:$G$19)+'DCF'!$G$18*(1+F$6)/($A9-F$6)/(1+$A9)^5-'Assumptions'!$B$10)/'Assumptions'!$B$9 -> 159.06879
A10: 0.08 | B10: =(SUMPRODUCT('DCF'!$C$18:$G$18,1/(1+$A10)^'DCF'!$C$19:$G$19)+'DCF'!$G$18*(1+B$6)/($A10-B$6)/(1+$A10)^5-'Assumptions'!$B$10)/'Assumptions'!$B$9 -> 98.208952 | C10: =(SUMPRODUCT('DCF'!$C$18:$G$18,1/(1+$A10)^'DCF'!$C$19:$G$19)+'DCF'!$G$18*(1+C$6)/($A10-C$6)/(1+$A10)^5-'Assumptions'!$B$10)/'Assumptions'!$B$9 -> 105.91386 | D10: =(SUMPRODUCT('DCF'!$C$18:$G$18,1/(1+$A10)^'DCF'!$C$19:$G$19)+'DCF'!$G$18*(1+D$6)/($A10-D$6)/(1+$A10)^5-'Assumptions'!$B$10)/'Assumptions'!$B$9 -> 115.01966 | E10: =(SUMPRODUCT('DCF'!$C$18:$G$18,1/(1+$A10)^'DCF'!$C$19:$G$19)+'DCF'!$G$18*(1+E$6)/($A10-E$6)/(1+$A10)^5-'Assumptions'!$B$10)/'Assumptions'!$B$9 -> 125.94663 | F10: =(SUMPRODUCT('DCF'!$C$18:$G$18,1/(1+$A10)^'DCF'!$C$19:$G$19)+'DCF'!$G$18*(1+F$6)/($A10-F$6)/(1+$A10)^5-'Assumptions'!$B$10)/'Assumptions'!$B$9 -> 139.3018
A11: 0.085 | B11: =(SUMPRODUCT('DCF'!$C$18:$G$18,1/(1+$A11)^'DCF'!$C$19:$G$19)+'DCF'!$G$18*(1+B$6)/($A11-B$6)/(1+$A11)^5-'Assumptions'!$B$10)/'Assumptions'!$B$9 -> 89.779644 | C11: =(SUMPRODUCT('DCF'!$C$18:$G$18,1/(1+$A11)^'DCF'!$C$19:$G$19)+'DCF'!$G$18*(1+C$6)/($A11-C$6)/(1+$A11)^5-'Assumptions'!$B$10)/'Assumptions'!$B$9 -> 96.262954 | D11: =(SUMPRODUCT('DCF'!$C$18:$G$18,1/(1+$A11)^'DCF'!$C$19:$G$19)+'DCF'!$G$18*(1+D$6)/($A11-D$6)/(1+$A11)^5-'Assumptions'!$B$10)/'Assumptions'!$B$9 -> 103.82682 | E11: =(SUMPRODUCT('DCF'!$C$18:$G$18,1/(1+$A11)^'DCF'!$C$19:$G$19)+'DCF'!$G$18*(1+E$6)/($A11-E$6)/(1+$A11)^5-'Assumptions'!$B$10)/'Assumptions'!$B$9 -> 112.76593 | F11: =(SUMPRODUCT('DCF'!$C$18:$G$18,1/(1+$A11)^'DCF'!$C$19:$G$19)+'DCF'!$G$18*(1+F$6)/($A11-F$6)/(1+$A11)^5-'Assumptions'!$B$10)/'Assumptions'!$B$9 -> 123.49286
A14: Value per share: revenue CAGR vs 2030 EBITDA margin
A15: CAGR / Margin | B15: 0.5 | C15: 0.52 | D15: 0.54 | E15: 0.56 | F15: 0.58
A16: 0.04 | B16: =((((('Historical'!$D$7*(1+$A16)^1)*('Historical'!$D$10+(B$15-'Historical'!$D$10)*1/5)*(1-'Assumptions'!$B$37)+('Historical'!$D$7*(1+$A16)^1)*'Assumptions'!$B$34*'Assumptions'!$B$37-('Historical'!$D$7*(1+$A16)^1)*'Assumptions'!$D$35-('Historical'!$D$7*(1+$A16)^1)*'Assumptions'!$B$36))/(1+'Assumptions'!$B$23)^1+((('Historical'!$D$7*(1+$A16)^2)*('Historical'!$D$10+(B$15-'Historical'!$D$10)*2/5)*(1-'Assumptions'!$B$37)+('Historical'!$D$7*(1+$A16)^2)*'Assumptions'!$B$34*'Assumptions'!$B$37-('Historical'!$D$7*(1+$A16)^2)*'Assumptions'!$E$35-('Historical'!$D$7*(1+$A16)^2)*'Assumptions'!$B$36))/(1+'Assumptions'!$B$23)^2+((('Historical'!$D$7*(1+$A16)^3)*('Historical'!$D$10+(B$15-'Historical'!$D$10)*3/5)*(1-'Assumptions'!$B$37)+('Historical'!$D$7*(1+$A16)^3)*'Assumptions'!$B$34*'Assumptions'!$B$37-('Historical'!$D$7*(1+$A16)^3)*'Assumptions'!$F$35-('Historical'!$D$7*(1+$A16)^3)*'Assumptions'!$B$36))/(1+'Assumptions'!$B$23)^3+((('Historical'!$D$7*(1+$A16)^4)*('Historical'!$D$10+(B$15-'Historical'!$D$10)*4/5)*(1-'Assumptions'!$B$37)+('Historical'!$D$7*(1+$A16)^4)*'Assumptions'!$B$34*'Assumptions'!$B$37-('Historical'!$D$7*(1+$A16)^4)*'Assumptions'!$G$35-('Historical'!$D$7*(1+$A16)^4)*'Assumptions'!$B$36))/(1+'Assumptions'!$B$23)^4+((('Historical'!$D$7*(1+$A16)^5)*('Historical'!$D$10+(B$15-'Historical'!$D$10)*5/5)*(1-'Assumptions'!$B$37)+('Historical'!$D$7*(1+$A16)^5)*'Assumptions'!$B$34*'Assumptions'!$B$37-('Historical'!$D$7*(1+$A16)^5)*'Assumptions'!$H$35-('Historical'!$D$7*(1+$A16)^5)*'Assumptions'!$B$36))/(1+'Assumptions'!$B$23)^5)+(((('Historical'!$D$7*(1+$A16)^5)*('Historical'!$D$10+(B$15-'Historical'!$D$10)*5/5)*(1-'Assumptions'!$B$37)+('Historical'!$D$7*(1+$A16)^5)*'Assumptions'!$B$34*'Assumptions'!$B$37-('Historical'!$D$7*(1+$A16)^5)*'Assumptions'!$H$35-('Historical'!$D$7*(1+$A16)^5)*'Assumptions'!$B$36))*(1+'Assumptions'!$B$38)/('Assumptions'!$B$23-'Assumptions'!$B$38)/(1+'Assumptions'!$B$23)^5)-'Assumptions'!$B$10)/'Assumptions'!$B$9 -> 99.677064 | C16: =((((('Historical'!$D$7*(1+$A16)^1)*('Historical'!$D$10+(C$15-'Historical'!$D$10)*1/5)*(1-'Assumptions'!$B$37)+('Historical'!$D$7*(1+$A16)^1)*'Assumptions'!$B$34*'Assumptions'!$B$37-('Historical'!$D$7*(1+$A16)^1)*'Assumptions'!$D$35-('Historical'!$D$7*(1+$A16)^1)*'Assumptions'!$B$36))/(1+'Assumptions'!$B$23)^1+((('Historical'!$D$7*(1+$A16)^2)*('Historical'!$D$10+(C$15-'Historical'!$D$10)*2/5)*(1-'Assumptions'!$B$37)+('Historical'!$D$7*(1+$A16)^2)*'Assumptions'!$B$34*'Assumptions'!$B$37-('Historical'!$D$7*(1+$A16)^2)*'Assumptions'!$E$35-('Historical'!$D$7*(1+$A16)^2)*'Assumptions'!$B$36))/(1+'Assumptions'!$B$23)^2+((('Historical'!$D$7*(1+$A16)^3)*('Historical'!$D$10+(C$15-'Historical'!$D$10)*3/5)*(1-'Assumptions'!$B$37)+('Historical'!$D$7*(1+$A16)^3)*'Assumptions'!$B$34*'Assumptions'!$B$37-('Historical'!$D$7*(1+$A16)^3)*'Assumptions'!$F$35-('Historical'!$D$7*(1+$A16)^3)*'Assumptions'!$B$36))/(1+'Assumptions'!$B$23)^3+((('Historical'!$D$7*(1+$A16)^4)*('Historical'!$D$10+(C$15-'Historical'!$D$10)*4/5)*(1-'Assumptions'!$B$37)+('Historical'!$D$7*(1+$A16)^4)*'Assumptions'!$B$34*'Assumptions'!$B$37-('Historical'!$D$7*(1+$A16)^4)*'Assumptions'!$G$35-('Historical'!$D$7*(1+$A16)^4)*'Assumptions'!$B$36))/(1+'Assumptions'!$B$23)^4+((('Historical'!$D$7*(1+$A16)^5)*('Historical'!$D$10+(C$15-'Historical'!$D$10)*5/5)*(1-'Assumptions'!$B$37)+('Historical'!$D$7*(1+$A16)^5)*'Assumptions'!$B$34*'Assumptions'!$B$37-('Historical'!$D$7*(1+$A16)^5)*'Assumptions'!$H$35-('Historical'!$D$7*(1+$A16)^5)*'Assumptions'!$B$36))/(1+'Assumptions'!$B$23)^5)+(((('Historical'!$D$7*(1+$A16)^5)*('Historical'!$D$10+(C$15-'Historical'!$D$10)*5/5)*(1-'Assumptions'!$B$37)+('Historical'!$D$7*(1+$A16)^5)*'Assumptions'!$B$34*'Assumptions'!$B$37-('Historical'!$D$7*(1+$A16)^5)*'Assumptions'!$H$35-('Historical'!$D$7*(1+$A16)^5)*'Assumptions'!$B$36))*(1+'Assumptions'!$B$38)/('Assumptions'!$B$23-'Assumptions'!$B$38)/(1+'Assumptions'!$B$23)^5)-'Assumptions'!$B$10)/'Assumptions'!$B$9 -> 104.83626 | D16: =((((('Historical'!$D$7*(1+$A16)^1)*('Historical'!$D$10+(D$15-'Historical'!$D$10)*1/5)*(1-'Assumptions'!$B$37)+('Historical'!$D$7*(1+$A16)^1)*'Assumptions'!$B$34*'Assumptions'!$B$37-('Historical'!$D$7*(1+$A16)^1)*'Assumptions'!$D$35-('Historical'!$D$7*(1+$A16)^1)*'Assumptions'!$B$36))/(1+'Assumptions'!$B$23)^1+((('Historical'!$D$7*(1+$A16)^2)*('Historical'!$D$10+(D$15-'Historical'!$D$10)*2/5)*(1-'Assumptions'!$B$37)+('Historical'!$D$7*(1+$A16)^2)*'Assumptions'!$B$34*'Assumptions'!$B$37-('Historical'!$D$7*(1+$A16)^2)*'Assumptions'!$E$35-('Historical'!$D$7*(1+$A16)^2)*'Assumptions'!$B$36))/(1+'Assumptions'!$B$23)^2+((('Historical'!$D$7*(1+$A16)^3)*('Historical'!$D$10+(D$15-'Historical'!$D$10)*3/5)*(1-'Assumptions'!$B$37)+('Historical'!$D$7*(1+$A16)^3)*'Assumptions'!$B$34*'Assumptions'!$B$37-('Historical'!$D$7*(1+$A16)^3)*'Assumptions'!$F$35-('Historical'!$D$7*(1+$A16)^3)*'Assumptions'!$B$36))/(1+'Assumptions'!$B$23)^3+((('Historical'!$D$7*(1+$A16)^4)*('Historical'!$D$10+(D$15-'Historical'!$D$10)*4/5)*(1-'Assumptions'!$B$37)+('Historical'!$D$7*(1+$A16)^4)*'Assumptions'!$B$34*'Assumptions'!$B$37-('Historical'!$D$7*(1+$A16)^4)*'Assumptions'!$G$35-('Historical'!$D$7*(1+$A16)^4)*'Assumptions'!$B$36))/(1+'Assumptions'!$B$23)^4+((('Historical'!$D$7*(1+$A16)^5)*('Historical'!$D$10+(D$15-'Historical'!$D$10)*5/5)*(1-'Assumptions'!$B$37)+('Historical'!$D$7*(1+$A16)^5)*'Assumptions'!$B$34*'Assumptions'!$B$37-('Historical'!$D$7*(1+$A16)^5)*'Assumptions'!$H$35-('Historical'!$D$7*(1+$A16)^5)*'Assumptions'!$B$36))/(1+'Assumptions'!$B$23)^5)+(((('Historical'!$D$7*(1+$A16)^5)*('Historical'!$D$10+(D$15-'Historical'!$D$10)*5/5)*(1-'Assumptions'!$B$37)+('Historical'!$D$7*(1+$A16)^5)*'Assumptions'!$B$34*'Assumptions'!$B$37-('Historical'!$D$7*(1+$A16)^5)*'Assumptions'!$H$35-('Historical'!$D$7*(1+$A16)^5)*'Assumptions'!$B$36))*(1+'Assumptions'!$B$38)/('Assumptions'!$B$23-'Assumptions'!$B$38)/(1+'Assumptions'!$B$23)^5)-'Assumptions'!$B$10)/'Assumptions'!$B$9 -> 109.99545 | E16: =((((('Historical'!$D$7*(1+$A16)^1)*('Historical'!$D$10+(E$15-'Historical'!$D$10)*1/5)*(1-'Assumptions'!$B$37)+('Historical'!$D$7*(1+$A16)^1)*'Assumptions'!$B$34*'Assumptions'!$B$37-('Historical'!$D$7*(1+$A16)^1)*'Assumptions'!$D$35-('Historical'!$D$7*(1+$A16)^1)*'Assumptions'!$B$36))/(1+'Assumptions'!$B$23)^1+((('Historical'!$D$7*(1+$A16)^2)*('Historical'!$D$10+(E$15-'Historical'!$D$10)*2/5)*(1-'Assumptions'!$B$37)+('Historical'!$D$7*(1+$A16)^2)*'Assumptions'!$B$34*'Assumptions'!$B$37-('Historical'!$D$7*(1+$A16)^2)*'Assumptions'!$E$35-('Historical'!$D$7*(1+$A16)^2)*'Assumptions'!$B$36))/(1+'Assumptions'!$B$23)^2+((('Historical'!$D$7*(1+$A16)^3)*('Historical'!$D$10+(E$15-'Historical'!$D$10)*3/5)*(1-'Assumptions'!$B$37)+('Historical'!$D$7*(1+$A16)^3)*'Assumptions'!$B$34*'Assumptions'!$B$37-('Historical'!$D$7*(1+$A16)^3)*'Assumptions'!$F$35-('Historical'!$D$7*(1+$A16)^3)*'Assumptions'!$B$36))/(1+'Assumptions'!$B$23)^3+((('Historical'!$D$7*(1+$A16)^4)*('Historical'!$D$10+(E$15-'Historical'!$D$10)*4/5)*(1-'Assumptions'!$B$37)+('Historical'!$D$7*(1+$A16)^4)*'Assumptions'!$B$34*'Assumptions'!$B$37-('Historical'!$D$7*(1+$A16)^4)*'Assumptions'!$G$35-('Historical'!$D$7*(1+$A16)^4)*'Assumptions'!$B$36))/(1+'Assumptions'!$B$23)^4+((('Historical'!$D$7*(1+$A16)^5)*('Historical'!$D$10+(E$15-'Historical'!$D$10)*5/5)*(1-'Assumptions'!$B$37)+('Historical'!$D$7*(1+$A16)^5)*'Assumptions'!$B$34*'Assumptions'!$B$37-('Historical'!$D$7*(1+$A16)^5)*'Assumptions'!$H$35-('Historical'!$D$7*(1+$A16)^5)*'Assumptions'!$B$36))/(1+'Assumptions'!$B$23)^5)+(((('Historical'!$D$7*(1+$A16)^5)*('Historical'!$D$10+(E$15-'Historical'!$D$10)*5/5)*(1-'Assumptions'!$B$37)+('Historical'!$D$7*(1+$A16)^5)*'Assumptions'!$B$34*'Assumptions'!$B$37-('Historical'!$D$7*(1+$A16)^5)*'Assumptions'!$H$35-('Historical'!$D$7*(1+$A16)^5)*'Assumptions'!$B$36))*(1+'Assumptions'!$B$38)/('Assumptions'!$B$23-'Assumptions'!$B$38)/(1+'Assumptions'!$B$23)^5)-'Assumptions'!$B$10)/'Assumptions'!$B$9 -> 115.15465 | F16: =((((('Historical'!$D$7*(1+$A16)^1)*('Historical'!$D$10+(F$15-'Historical'!$D$10)*1/5)*(1-'Assumptions'!$B$37)+('Historical'!$D$7*(1+$A16)^1)*'Assumptions'!$B$34*'Assumptions'!$B$37-('Historical'!$D$7*(1+$A16)^1)*'Assumptions'!$D$35-('Historical'!$D$7*(1+$A16)^1)*'Assumptions'!$B$36))/(1+'Assumptions'!$B$23)^1+((('Historical'!$D$7*(1+$A16)^2)*('Historical'!$D$10+(F$15-'Historical'!$D$10)*2/5)*(1-'Assumptions'!$B$37)+('Historical'!$D$7*(1+$A16)^2)*'Assumptions'!$B$34*'Assumptions'!$B$37-('Historical'!$D$7*(1+$A16)^2)*'Assumptions'!$E$35-('Historical'!$D$7*(1+$A16)^2)*'Assumptions'!$B$36))/(1+'Assumptions'!$B$23)^2+((('Historical'!$D$7*(1+$A16)^3)*('Historical'!$D$10+(F$15-'Historical'!$D$10)*3/5)*(1-'Assumptions'!$B$37)+('Historical'!$D$7*(1+$A16)^3)*'Assumptions'!$B$34*'Assumptions'!$B$37-('Historical'!$D$7*(1+$A16)^3)*'Assumptions'!$F$35-('Historical'!$D$7*(1+$A16)^3)*'Assumptions'!$B$36))/(1+'Assumptions'!$B$23)^3+((('Historical'!$D$7*(1+$A16)^4)*('Historical'!$D$10+(F$15-'Historical'!$D$10)*4/5)*(1-'Assumptions'!$B$37)+('Historical'!$D$7*(1+$A16)^4)*'Assumptions'!$B$34*'Assumptions'!$B$37-('Historical'!$D$7*(1+$A16)^4)*'Assumptions'!$G$35-('Historical'!$D$7*(1+$A16)^4)*'Assumptions'!$B$36))/(1+'Assumptions'!$B$23)^4+((('Historical'!$D$7*(1+$A16)^5)*('Historical'!$D$10+(F$15-'Historical'!$D$10)*5/5)*(1-'Assumptions'!$B$37)+('Historical'!$D$7*(1+$A16)^5)*'Assumptions'!$B$34*'Assumptions'!$B$37-('Historical'!$D$7*(1+$A16)^5)*'Assumptions'!$H$35-('Historical'!$D$7*(1+$A16)^5)*'Assumptions'!$B$36))/(1+'Assumptions'!$B$23)^5)+(((('Historical'!$D$7*(1+$A16)^5)*('Historical'!$D$10+(F$15-'Historical'!$D$10)*5/5)*(1-'Assumptions'!$B$37)+('Historical'!$D$7*(1+$A16)^5)*'Assumptions'!$B$34*'Assumptions'!$B$37-('Historical'!$D$7*(1+$A16)^5)*'Assumptions'!$H$35-('Historical'!$D$7*(1+$A16)^5)*'Assumptions'!$B$36))*(1+'Assumptions'!$B$38)/('Assumptions'!$B$23-'Assumptions'!$B$38)/(1+'Assumptions'!$B$23)^5)-'Assumptions'!$B$10)/'Assumptions'!$B$9 -> 120.31384
A17: 0.05 | B17: =((((('Historical'!$D$7*(1+$A17)^1)*('Historical'!$D$10+(B$15-'Historical'!$D$10)*1/5)*(1-'Assumptions'!$B$37)+('Historical'!$D$7*(1+$A17)^1)*'Assumptions'!$B$34*'Assumptions'!$B$37-('Historical'!$D$7*(1+$A17)^1)*'Assumptions'!$D$35-('Historical'!$D$7*(1+$A17)^1)*'Assumptions'!$B$36))/(1+'Assumptions'!$B$23)^1+((('Historical'!$D$7*(1+$A17)^2)*('Historical'!$D$10+(B$15-'Historical'!$D$10)*2/5)*(1-'Assumptions'!$B$37)+('Historical'!$D$7*(1+$A17)^2)*'Assumptions'!$B$34*'Assumptions'!$B$37-('Historical'!$D$7*(1+$A17)^2)*'Assumptions'!$E$35-('Historical'!$D$7*(1+$A17)^2)*'Assumptions'!$B$36))/(1+'Assumptions'!$B$23)^2+((('Historical'!$D$7*(1+$A17)^3)*('Historical'!$D$10+(B$15-'Historical'!$D$10)*3/5)*(1-'Assumptions'!$B$37)+('Historical'!$D$7*(1+$A17)^3)*'Assumptions'!$B$34*'Assumptions'!$B$37-('Historical'!$D$7*(1+$A17)^3)*'Assumptions'!$F$35-('Historical'!$D$7*(1+$A17)^3)*'Assumptions'!$B$36))/(1+'Assumptions'!$B$23)^3+((('Historical'!$D$7*(1+$A17)^4)*('Historical'!$D$10+(B$15-'Historical'!$D$10)*4/5)*(1-'Assumptions'!$B$37)+('Historical'!$D$7*(1+$A17)^4)*'Assumptions'!$B$34*'Assumptions'!$B$37-('Historical'!$D$7*(1+$A17)^4)*'Assumptions'!$G$35-('Historical'!$D$7*(1+$A17)^4)*'Assumptions'!$B$36))/(1+'Assumptions'!$B$23)^4+((('Historical'!$D$7*(1+$A17)^5)*('Historical'!$D$10+(B$15-'Historical'!$D$10)*5/5)*(1-'Assumptions'!$B$37)+('Historical'!$D$7*(1+$A17)^5)*'Assumptions'!$B$34*'Assumptions'!$B$37-('Historical'!$D$7*(1+$A17)^5)*'Assumptions'!$H$35-('Historical'!$D$7*(1+$A17)^5)*'Assumptions'!$B$36))/(1+'Assumptions'!$B$23)^5)+(((('Historical'!$D$7*(1+$A17)^5)*('Historical'!$D$10+(B$15-'Historical'!$D$10)*5/5)*(1-'Assumptions'!$B$37)+('Historical'!$D$7*(1+$A17)^5)*'Assumptions'!$B$34*'Assumptions'!$B$37-('Historical'!$D$7*(1+$A17)^5)*'Assumptions'!$H$35-('Historical'!$D$7*(1+$A17)^5)*'Assumptions'!$B$36))*(1+'Assumptions'!$B$38)/('Assumptions'!$B$23-'Assumptions'!$B$38)/(1+'Assumptions'!$B$23)^5)-'Assumptions'!$B$10)/'Assumptions'!$B$9 -> 104.86004 | C17: =((((('Historical'!$D$7*(1+$A17)^1)*('Historical'!$D$10+(C$15-'Historical'!$D$10)*1/5)*(1-'Assumptions'!$B$37)+('Historical'!$D$7*(1+$A17)^1)*'Assumptions'!$B$34*'Assumptions'!$B$37-('Historical'!$D$7*(1+$A17)^1)*'Assumptions'!$D$35-('Historical'!$D$7*(1+$A17)^1)*'Assumptions'!$B$36))/(1+'Assumptions'!$B$23)^1+((('Historical'!$D$7*(1+$A17)^2)*('Historical'!$D$10+(C$15-'Historical'!$D$10)*2/5)*(1-'Assumptions'!$B$37)+('Historical'!$D$7*(1+$A17)^2)*'Assumptions'!$B$34*'Assumptions'!$B$37-('Historical'!$D$7*(1+$A17)^2)*'Assumptions'!$E$35-('Historical'!$D$7*(1+$A17)^2)*'Assumptions'!$B$36))/(1+'Assumptions'!$B$23)^2+((('Historical'!$D$7*(1+$A17)^3)*('Historical'!$D$10+(C$15-'Historical'!$D$10)*3/5)*(1-'Assumptions'!$B$37)+('Historical'!$D$7*(1+$A17)^3)*'Assumptions'!$B$34*'Assumptions'!$B$37-('Historical'!$D$7*(1+$A17)^3)*'Assumptions'!$F$35-('Historical'!$D$7*(1+$A17)^3)*'Assumptions'!$B$36))/(1+'Assumptions'!$B$23)^3+((('Historical'!$D$7*(1+$A17)^4)*('Historical'!$D$10+(C$15-'Historical'!$D$10)*4/5)*(1-'Assumptions'!$B$37)+('Historical'!$D$7*(1+$A17)^4)*'Assumptions'!$B$34*'Assumptions'!$B$37-('Historical'!$D$7*(1+$A17)^4)*'Assumptions'!$G$35-('Historical'!$D$7*(1+$A17)^4)*'Assumptions'!$B$36))/(1+'Assumptions'!$B$23)^4+((('Historical'!$D$7*(1+$A17)^5)*('Historical'!$D$10+(C$15-'Historical'!$D$10)*5/5)*(1-'Assumptions'!$B$37)+('Historical'!$D$7*(1+$A17)^5)*'Assumptions'!$B$34*'Assumptions'!$B$37-('Historical'!$D$7*(1+$A17)^5)*'Assumptions'!$H$35-('Historical'!$D$7*(1+$A17)^5)*'Assumptions'!$B$36))/(1+'Assumptions'!$B$23)^5)+(((('Historical'!$D$7*(1+$A17)^5)*('Historical'!$D$10+(C$15-'Historical'!$D$10)*5/5)*(1-'Assumptions'!$B$37)+('Historical'!$D$7*(1+$A17)^5)*'Assumptions'!$B$34*'Assumptions'!$B$37-('Historical'!$D$7*(1+$A17)^5)*'Assumptions'!$H$35-('Historical'!$D$7*(1+$A17)^5)*'Assumptions'!$B$36))*(1+'Assumptions'!$B$38)/('Assumptions'!$B$23-'Assumptions'!$B$38)/(1+'Assumptions'!$B$23)^5)-'Assumptions'!$B$10)/'Assumptions'!$B$9 -> 110.26232 | D17: =((((('Historical'!$D$7*(1+$A17)^1)*('Historical'!$D$10+(D$15-'Historical'!$D$10)*1/5)*(1-'Assumptions'!$B$37)+('Historical'!$D$7*(1+$A17)^1)*'Assumptions'!$B$34*'Assumptions'!$B$37-('Historical'!$D$7*(1+$A17)^1)*'Assumptions'!$D$35-('Historical'!$D$7*(1+$A17)^1)*'Assumptions'!$B$36))/(1+'Assumptions'!$B$23)^1+((('Historical'!$D$7*(1+$A17)^2)*('Historical'!$D$10+(D$15-'Historical'!$D$10)*2/5)*(1-'Assumptions'!$B$37)+('Historical'!$D$7*(1+$A17)^2)*'Assumptions'!$B$34*'Assumptions'!$B$37-('Historical'!$D$7*(1+$A17)^2)*'Assumptions'!$E$35-('Historical'!$D$7*(1+$A17)^2)*'Assumptions'!$B$36))/(1+'Assumptions'!$B$23)^2+((('Historical'!$D$7*(1+$A17)^3)*('Historical'!$D$10+(D$15-'Historical'!$D$10)*3/5)*(1-'Assumptions'!$B$37)+('Historical'!$D$7*(1+$A17)^3)*'Assumptions'!$B$34*'Assumptions'!$B$37-('Historical'!$D$7*(1+$A17)^3)*'Assumptions'!$F$35-('Historical'!$D$7*(1+$A17)^3)*'Assumptions'!$B$36))/(1+'Assumptions'!$B$23)^3+((('Historical'!$D$7*(1+$A17)^4)*('Historical'!$D$10+(D$15-'Historical'!$D$10)*4/5)*(1-'Assumptions'!$B$37)+('Historical'!$D$7*(1+$A17)^4)*'Assumptions'!$B$34*'Assumptions'!$B$37-('Historical'!$D$7*(1+$A17)^4)*'Assumptions'!$G$35-('Historical'!$D$7*(1+$A17)^4)*'Assumptions'!$B$36))/(1+'Assumptions'!$B$23)^4+((('Historical'!$D$7*(1+$A17)^5)*('Historical'!$D$10+(D$15-'Historical'!$D$10)*5/5)*(1-'Assumptions'!$B$37)+('Historical'!$D$7*(1+$A17)^5)*'Assumptions'!$B$34*'Assumptions'!$B$37-('Historical'!$D$7*(1+$A17)^5)*'Assumptions'!$H$35-('Historical'!$D$7*(1+$A17)^5)*'Assumptions'!$B$36))/(1+'Assumptions'!$B$23)^5)+(((('Historical'!$D$7*(1+$A17)^5)*('Historical'!$D$10+(D$15-'Historical'!$D$10)*5/5)*(1-'Assumptions'!$B$37)+('Historical'!$D$7*(1+$A17)^5)*'Assumptions'!$B$34*'Assumptions'!$B$37-('Historical'!$D$7*(1+$A17)^5)*'Assumptions'!$H$35-('Historical'!$D$7*(1+$A17)^5)*'Assumptions'!$B$36))*(1+'Assumptions'!$B$38)/('Assumptions'!$B$23-'Assumptions'!$B$38)/(1+'Assumptions'!$B$23)^5)-'Assumptions'!$B$10)/'Assumptions'!$B$9 -> 115.6646 | E17: =((((('Historical'!$D$7*(1+$A17)^1)*('Historical'!$D$10+(E$15-'Historical'!$D$10)*1/5)*(1-'Assumptions'!$B$37)+('Historical'!$D$7*(1+$A17)^1)*'Assumptions'!$B$34*'Assumptions'!$B$37-('Historical'!$D$7*(1+$A17)^1)*'Assumptions'!$D$35-('Historical'!$D$7*(1+$A17)^1)*'Assumptions'!$B$36))/(1+'Assumptions'!$B$23)^1+((('Historical'!$D$7*(1+$A17)^2)*('Historical'!$D$10+(E$15-'Historical'!$D$10)*2/5)*(1-'Assumptions'!$B$37)+('Historical'!$D$7*(1+$A17)^2)*'Assumptions'!$B$34*'Assumptions'!$B$37-('Historical'!$D$7*(1+$A17)^2)*'Assumptions'!$E$35-('Historical'!$D$7*(1+$A17)^2)*'Assumptions'!$B$36))/(1+'Assumptions'!$B$23)^2+((('Historical'!$D$7*(1+$A17)^3)*('Historical'!$D$10+(E$15-'Historical'!$D$10)*3/5)*(1-'Assumptions'!$B$37)+('Historical'!$D$7*(1+$A17)^3)*'Assumptions'!$B$34*'Assumptions'!$B$37-('Historical'!$D$7*(1+$A17)^3)*'Assumptions'!$F$35-('Historical'!$D$7*(1+$A17)^3)*'Assumptions'!$B$36))/(1+'Assumptions'!$B$23)^3+((('Historical'!$D$7*(1+$A17)^4)*('Historical'!$D$10+(E$15-'Historical'!$D$10)*4/5)*(1-'Assumptions'!$B$37)+('Historical'!$D$7*(1+$A17)^4)*'Assumptions'!$B$34*'Assumptions'!$B$37-('Historical'!$D$7*(1+$A17)^4)*'Assumptions'!$G$35-('Historical'!$D$7*(1+$A17)^4)*'Assumptions'!$B$36))/(1+'Assumptions'!$B$23)^4+((('Historical'!$D$7*(1+$A17)^5)*('Historical'!$D$10+(E$15-'Historical'!$D$10)*5/5)*(1-'Assumptions'!$B$37)+('Historical'!$D$7*(1+$A17)^5)*'Assumptions'!$B$34*'Assumptions'!$B$37-('Historical'!$D$7*(1+$A17)^5)*'Assumptions'!$H$35-('Historical'!$D$7*(1+$A17)^5)*'Assumptions'!$B$36))/(1+'Assumptions'!$B$23)^5)+(((('Historical'!$D$7*(1+$A17)^5)*('Historical'!$D$10+(E$15-'Historical'!$D$10)*5/5)*(1-'Assumptions'!$B$37)+('Historical'!$D$7*(1+$A17)^5)*'Assumptions'!$B$34*'Assumptions'!$B$37-('Historical'!$D$7*(1+$A17)^5)*'Assumptions'!$H$35-('Historical'!$D$7*(1+$A17)^5)*'Assumptions'!$B$36))*(1+'Assumptions'!$B$38)/('Assumptions'!$B$23-'Assumptions'!$B$38)/(1+'Assumptions'!$B$23)^5)-'Assumptions'!$B$10)/'Assumptions'!$B$9 -> 121.06688 | F17: =((((('Historical'!$D$7*(1+$A17)^1)*('Historical'!$D$10+(F$15-'Historical'!$D$10)*1/5)*(1-'Assumptions'!$B$37)+('Historical'!$D$7*(1+$A17)^1)*'Assumptions'!$B$34*'Assumptions'!$B$37-('Historical'!$D$7*(1+$A17)^1)*'Assumptions'!$D$35-('Historical'!$D$7*(1+$A17)^1)*'Assumptions'!$B$36))/(1+'Assumptions'!$B$23)^1+((('Historical'!$D$7*(1+$A17)^2)*('Historical'!$D$10+(F$15-'Historical'!$D$10)*2/5)*(1-'Assumptions'!$B$37)+('Historical'!$D$7*(1+$A17)^2)*'Assumptions'!$B$34*'Assumptions'!$B$37-('Historical'!$D$7*(1+$A17)^2)*'Assumptions'!$E$35-('Historical'!$D$7*(1+$A17)^2)*'Assumptions'!$B$36))/(1+'Assumptions'!$B$23)^2+((('Historical'!$D$7*(1+$A17)^3)*('Historical'!$D$10+(F$15-'Historical'!$D$10)*3/5)*(1-'Assumptions'!$B$37)+('Historical'!$D$7*(1+$A17)^3)*'Assumptions'!$B$34*'Assumptions'!$B$37-('Historical'!$D$7*(1+$A17)^3)*'Assumptions'!$F$35-('Historical'!$D$7*(1+$A17)^3)*'Assumptions'!$B$36))/(1+'Assumptions'!$B$23)^3+((('Historical'!$D$7*(1+$A17)^4)*('Historical'!$D$10+(F$15-'Historical'!$D$10)*4/5)*(1-'Assumptions'!$B$37)+('Historical'!$D$7*(1+$A17)^4)*'Assumptions'!$B$34*'Assumptions'!$B$37-('Historical'!$D$7*(1+$A17)^4)*'Assumptions'!$G$35-('Historical'!$D$7*(1+$A17)^4)*'Assumptions'!$B$36))/(1+'Assumptions'!$B$23)^4+((('Historical'!$D$7*(1+$A17)^5)*('Historical'!$D$10+(F$15-'Historical'!$D$10)*5/5)*(1-'Assumptions'!$B$37)+('Historical'!$D$7*(1+$A17)^5)*'Assumptions'!$B$34*'Assumptions'!$B$37-('Historical'!$D$7*(1+$A17)^5)*'Assumptions'!$H$35-('Historical'!$D$7*(1+$A17)^5)*'Assumptions'!$B$36))/(1+'Assumptions'!$B$23)^5)+(((('Historical'!$D$7*(1+$A17)^5)*('Historical'!$D$10+(F$15-'Historical'!$D$10)*5/5)*(1-'Assumptions'!$B$37)+('Historical'!$D$7*(1+$A17)^5)*'Assumptions'!$B$34*'Assumptions'!$B$37-('Historical'!$D$7*(1+$A17)^5)*'Assumptions'!$H$35-('Historical'!$D$7*(1+$A17)^5)*'Assumptions'!$B$36))*(1+'Assumptions'!$B$38)/('Assumptions'!$B$23-'Assumptions'!$B$38)/(1+'Assumptions'!$B$23)^5)-'Assumptions'!$B$10)/'Assumptions'!$B$9 -> 126.46916
